<?xml version="1.0" ?><root>
<report><version>2</version><sessionid>b486a23b7565899d5e7a6056</sessionid><type>desync</type><sku>ea.maxis.sims4_64.15.pc</sku><createtime>2020-03-24 21:59:39</createtime><buildsignature>Local.Unknown.Unknown.1.61.15.1020-1.200.000.440.Release</buildsignature><categoryid>cpp_message.py:167</categoryid><desyncid>b486a23b7565899d5e7a6056</desyncid><systemconfig/><screenshot/><desyncdata>Exception raised while trying to run a test event in test_events.py: (IndexError: list assignment index (0) out of range)&#13;&#10;Traceback (most recent call last):&#13;&#10;Caught and logged:&#13;&#10;  File "T:\InGame\Gameplay\Scripts\Core\sims4\utils.py", line 179, in wrapper&#13;&#10;  File "T:\InGame\Gameplay\Scripts\Server\areaserver.py", line 206, in c_api_server_tick&#13;&#10;  File "T:\InGame\Gameplay\Scripts\Server\zone.py", line 465, in update&#13;&#10;  File "T:\InGame\Gameplay\Scripts\Server\zone_spin_up_service.py", line 1460, in update&#13;&#10;  File "T:\InGame\Gameplay\Scripts\Server\zone_spin_up_service.py", line 1166, in on_enter&#13;&#10;  File "T:\InGame\Gameplay\Scripts\Server\sims\sim_info.py", line 1034, in start_aspiration_tracker_on_instantiation&#13;&#10;  File "T:\InGame\Gameplay\Scripts\Server\aspirations\aspirations.py", line 129, in initialize_aspiration&#13;&#10;  File "T:\InGame\Gameplay\Scripts\Server\aspirations\aspirations.py", line 112, in _activate_aspiration&#13;&#10;  File "T:\InGame\Gameplay\Scripts\Server\aspirations\aspirations.py", line 146, in process_test_events_for_aspiration&#13;&#10;  File "T:\InGame\Gameplay\Scripts\Server\event_testing\event_manager_service.py", line 237, in process_test_events_for_objective_updates&#13;&#10;  File "T:\InGame\Gameplay\Scripts\Server\event_testing\event_manager_service.py", line 371, in _process_test_event&#13;&#10;  File "T:\InGame\Gameplay\Scripts\Server\event_testing\test_events.py", line 174, in wrapper&#13;&#10;KeyError: (&lt;event_testing.tests_with_data.TotalTimeElapsedByTagTest object at 0x00007FF48B742390&gt;, frozenset({('objective_guid64', 25807), ('data_object', &lt;event_testing.event_data_object.EventDataObject object at 0x00007FF48E01BAD0&gt;)}))&#13;&#10;&#13;&#10;During handling of the above exception, another exception occurred:&#13;&#10;&#13;&#10;Traceback (most recent call last):&#13;&#10;  File "T:\InGame\Gameplay\Scripts\Server\event_testing\event_manager_service.py", line 369, in _process_test_event&#13;&#10;  File "T:\InGame\Gameplay\Scripts\Server\aspirations\aspiration_tuning.py", line 64, in handle_event&#13;&#10;  File "T:\InGame\Gameplay\Scripts\Server\event_testing\event_data_tracker.py", line 185, in handle_event&#13;&#10;  File "T:\InGame\Gameplay\Scripts\Server\event_testing\objective_tuning.py", line 1046, in run_test&#13;&#10;  File "T:\InGame\Gameplay\Scripts\Server\event_testing\resolver.py", line 830, in __call__&#13;&#10;  File "T:\InGame\Gameplay\Scripts\Server\event_testing\resolver.py", line 130, in __call__&#13;&#10;  File "T:\InGame\Gameplay\Scripts\Server\event_testing\test_events.py", line 176, in wrapper&#13;&#10;  File "T:\InGame\Gameplay\Scripts\Server\event_testing\tests_with_data.py", line 1175, in __call__&#13;&#10;  File "T:\InGame\Gameplay\Scripts\Core\google\protobuf\internal\cpp_message.py", line 167, in __getitem__&#13;&#10;IndexError: list assignment index (0) out of range&#13;&#10;rtim=0&#13;&#10;Client Session Time: 31.45&#13; &#10;Num Save Errors: 0&#13; &#10;Num Load Errors: 0&#13; &#10;Current Game State: 0xdd4141d5&#13; &#10;Origin Version: 10,5,8,17910&#13; &#10;Modded: False&#13; &#10;SystemInfo: Windows 10 10.0.18363 GPU: Intel(R) HD Graphics igdumd64.dll 8.15.10.2900, GUID: D7B78E66-4306-11CF-9D79-0820B2C2C535&#13; &#10;</desyncdata></report>
<report><version>2</version><sessionid>b486a23b7565899d5e7a6056</sessionid><type>desync</type><sku>ea.maxis.sims4_64.15.pc</sku><createtime>2020-03-24 22:00:19</createtime><buildsignature>Local.Unknown.Unknown.1.61.15.1020-1.200.000.440.Release</buildsignature><categoryid>cpp_message.py:167</categoryid><desyncid>b486a23b7565899d5e7a6056</desyncid><systemconfig/><screenshot/><desyncdata>Exception raised while trying to run a test event in test_events.py: (IndexError: list assignment index (0) out of range)&#13;&#10;Traceback (most recent call last):&#13;&#10;Caught and logged:&#13;&#10;  File "T:\InGame\Gameplay\Scripts\Core\sims4\utils.py", line 179, in wrapper&#13;&#10;  File "T:\InGame\Gameplay\Scripts\Server\areaserver.py", line 206, in c_api_server_tick&#13;&#10;  File "T:\InGame\Gameplay\Scripts\Server\zone.py", line 469, in update&#13;&#10;  File "T:\InGame\Gameplay\Scripts\Server\time_service.py", line 112, in update&#13;&#10;  File "T:\InGame\Gameplay\Scripts\Server\scheduling.py", line 217, in simulate&#13;&#10;  File "T:\InGame\Gameplay\Scripts\Server\elements.py", line 385, in _resume&#13;&#10;  File "T:\InGame\Gameplay\Scripts\Server\sims\sim.py", line 3755, in _process_interaction_gen&#13;&#10;  File "T:\InGame\Gameplay\Scripts\Server\interactions\interaction_queue.py", line 786, in process_one_interaction_gen&#13;&#10;  File "T:\InGame\Gameplay\Scripts\Server\interactions\si_state.py", line 944, in process_gen&#13;&#10;  File "T:\InGame\Gameplay\Scripts\Server\interactions\si_state.py", line 323, in remove_gen&#13;&#10;  File "T:\InGame\Gameplay\Scripts\Server\interactions\si_state.py", line 1143, in _remove_gen&#13;&#10;  File "T:\InGame\Gameplay\Scripts\Server\interactions\base\super_interaction.py", line 4945, in on_removed_from_si_state&#13;&#10;  File "T:\InGame\Gameplay\Scripts\Server\interactions\base\super_interaction.py", line 4957, in _exited_pipeline&#13;&#10;  File "T:\InGame\Gameplay\Scripts\Server\interactions\base\interaction.py", line 6718, in _exited_pipeline&#13;&#10;  File "T:\InGame\Gameplay\Scripts\Server\interactions\base\interaction.py", line 5781, in _trigger_interaction_complete_test_event&#13;&#10;  File "T:\InGame\Gameplay\Scripts\Server\event_testing\event_manager_service.py", line 262, in process_event&#13;&#10;  File "T:\InGame\Gameplay\Scripts\Server\event_testing\event_manager_service.py", line 371, in _process_test_event&#13;&#10;  File "T:\InGame\Gameplay\Scripts\Server\event_testing\test_events.py", line 174, in wrapper&#13;&#10;KeyError: (&lt;event_testing.tests_with_data.TotalTimeElapsedByTagTest object at 0x00007FF48B742390&gt;, frozenset({('objective_guid64', 25807), ('data_object', &lt;event_testing.event_data_object.EventDataObject object at 0x00007FF48E01BAD0&gt;)}))&#13;&#10;&#13;&#10;During handling of the above exception, another exception occurred:&#13;&#10;&#13;&#10;Traceback (most recent call last):&#13;&#10;  File "T:\InGame\Gameplay\Scripts\Server\event_testing\event_manager_service.py", line 369, in _process_test_event&#13;&#10;  File "T:\InGame\Gameplay\Scripts\Server\aspirations\aspiration_tuning.py", line 64, in handle_event&#13;&#10;  File "T:\InGame\Gameplay\Scripts\Server\event_testing\event_data_tracker.py", line 185, in handle_event&#13;&#10;  File "T:\InGame\Gameplay\Scripts\Server\event_testing\objective_tuning.py", line 1046, in run_test&#13;&#10;  File "T:\InGame\Gameplay\Scripts\Server\event_testing\resolver.py", line 830, in __call__&#13;&#10;  File "T:\InGame\Gameplay\Scripts\Server\event_testing\resolver.py", line 130, in __call__&#13;&#10;  File "T:\InGame\Gameplay\Scripts\Server\event_testing\test_events.py", line 176, in wrapper&#13;&#10;  File "T:\InGame\Gameplay\Scripts\Server\event_testing\tests_with_data.py", line 1175, in __call__&#13;&#10;  File "T:\InGame\Gameplay\Scripts\Core\google\protobuf\internal\cpp_message.py", line 167, in __getitem__&#13;&#10;IndexError: list assignment index (0) out of range&#13;&#10;rtim=0&#13;&#10;Client Session Time: 31.45&#13; &#10;Num Save Errors: 0&#13; &#10;Num Load Errors: 0&#13; &#10;Current Game State: 0xdd4141d5&#13; &#10;Origin Version: 10,5,8,17910&#13; &#10;Modded: False&#13; &#10;SystemInfo: Windows 10 10.0.18363 GPU: Intel(R) HD Graphics igdumd64.dll 8.15.10.2900, GUID: D7B78E66-4306-11CF-9D79-0820B2C2C535&#13; &#10;</desyncdata></report>
<report><version>2</version><sessionid>b486a23b7565899d5e7a6056</sessionid><type>desync</type><sku>ea.maxis.sims4_64.15.pc</sku><createtime>2020-03-24 22:01:30</createtime><buildsignature>Local.Unknown.Unknown.1.61.15.1020-1.200.000.440.Release</buildsignature><categoryid>cpp_message.py:167</categoryid><desyncid>b486a23b7565899d5e7a6056</desyncid><systemconfig/><screenshot/><desyncdata>Exception raised while trying to run a test event in test_events.py: (IndexError: list assignment index (0) out of range)&#13;&#10;Traceback (most recent call last):&#13;&#10;Caught and logged:&#13;&#10;  File "T:\InGame\Gameplay\Scripts\Core\sims4\utils.py", line 179, in wrapper&#13;&#10;  File "T:\InGame\Gameplay\Scripts\Server\areaserver.py", line 206, in c_api_server_tick&#13;&#10;  File "T:\InGame\Gameplay\Scripts\Server\zone.py", line 469, in update&#13;&#10;  File "T:\InGame\Gameplay\Scripts\Server\time_service.py", line 112, in update&#13;&#10;  File "T:\InGame\Gameplay\Scripts\Server\scheduling.py", line 217, in simulate&#13;&#10;  File "T:\InGame\Gameplay\Scripts\Server\elements.py", line 385, in _resume&#13;&#10;  File "T:\InGame\Gameplay\Scripts\Server\sims\sim.py", line 3755, in _process_interaction_gen&#13;&#10;  File "T:\InGame\Gameplay\Scripts\Server\interactions\interaction_queue.py", line 786, in process_one_interaction_gen&#13;&#10;  File "T:\InGame\Gameplay\Scripts\Server\interactions\si_state.py", line 944, in process_gen&#13;&#10;  File "T:\InGame\Gameplay\Scripts\Server\interactions\si_state.py", line 323, in remove_gen&#13;&#10;  File "T:\InGame\Gameplay\Scripts\Server\interactions\si_state.py", line 1143, in _remove_gen&#13;&#10;  File "T:\InGame\Gameplay\Scripts\Server\interactions\base\super_interaction.py", line 4945, in on_removed_from_si_state&#13;&#10;  File "T:\InGame\Gameplay\Scripts\Server\interactions\base\super_interaction.py", line 4957, in _exited_pipeline&#13;&#10;  File "T:\InGame\Gameplay\Scripts\Server\interactions\base\interaction.py", line 6718, in _exited_pipeline&#13;&#10;  File "T:\InGame\Gameplay\Scripts\Server\interactions\base\interaction.py", line 5781, in _trigger_interaction_complete_test_event&#13;&#10;  File "T:\InGame\Gameplay\Scripts\Server\event_testing\event_manager_service.py", line 262, in process_event&#13;&#10;  File "T:\InGame\Gameplay\Scripts\Server\event_testing\event_manager_service.py", line 371, in _process_test_event&#13;&#10;  File "T:\InGame\Gameplay\Scripts\Server\event_testing\test_events.py", line 174, in wrapper&#13;&#10;KeyError: (&lt;event_testing.tests_with_data.TotalTimeElapsedByTagTest object at 0x00007FF48B742390&gt;, frozenset({('objective_guid64', 25807), ('data_object', &lt;event_testing.event_data_object.EventDataObject object at 0x00007FF48E01BAD0&gt;)}))&#13;&#10;&#13;&#10;During handling of the above exception, another exception occurred:&#13;&#10;&#13;&#10;Traceback (most recent call last):&#13;&#10;  File "T:\InGame\Gameplay\Scripts\Server\event_testing\event_manager_service.py", line 369, in _process_test_event&#13;&#10;  File "T:\InGame\Gameplay\Scripts\Server\aspirations\aspiration_tuning.py", line 64, in handle_event&#13;&#10;  File "T:\InGame\Gameplay\Scripts\Server\event_testing\event_data_tracker.py", line 185, in handle_event&#13;&#10;  File "T:\InGame\Gameplay\Scripts\Server\event_testing\objective_tuning.py", line 1046, in run_test&#13;&#10;  File "T:\InGame\Gameplay\Scripts\Server\event_testing\resolver.py", line 830, in __call__&#13;&#10;  File "T:\InGame\Gameplay\Scripts\Server\event_testing\resolver.py", line 130, in __call__&#13;&#10;  File "T:\InGame\Gameplay\Scripts\Server\event_testing\test_events.py", line 176, in wrapper&#13;&#10;  File "T:\InGame\Gameplay\Scripts\Server\event_testing\tests_with_data.py", line 1175, in __call__&#13;&#10;  File "T:\InGame\Gameplay\Scripts\Core\google\protobuf\internal\cpp_message.py", line 167, in __getitem__&#13;&#10;IndexError: list assignment index (0) out of range&#13;&#10;rtim=0&#13;&#10;Client Session Time: 31.45&#13; &#10;Num Save Errors: 0&#13; &#10;Num Load Errors: 0&#13; &#10;Current Game State: 0xdd4141d5&#13; &#10;Origin Version: 10,5,8,17910&#13; &#10;Modded: False&#13; &#10;SystemInfo: Windows 10 10.0.18363 GPU: Intel(R) HD Graphics igdumd64.dll 8.15.10.2900, GUID: D7B78E66-4306-11CF-9D79-0820B2C2C535&#13; &#10;</desyncdata></report>
<report><version>2</version><sessionid>b486a23b7565899d5e7a6056</sessionid><type>desync</type><sku>ea.maxis.sims4_64.15.pc</sku><createtime>2020-03-24 22:01:37</createtime><buildsignature>Local.Unknown.Unknown.1.61.15.1020-1.200.000.440.Release</buildsignature><categoryid>cpp_message.py:167</categoryid><desyncid>b486a23b7565899d5e7a6056</desyncid><systemconfig/><screenshot/><desyncdata>Exception raised while trying to run a test event in test_events.py: (IndexError: list assignment index (0) out of range)&#13;&#10;Traceback (most recent call last):&#13;&#10;Caught and logged:&#13;&#10;  File "T:\InGame\Gameplay\Scripts\Core\sims4\utils.py", line 179, in wrapper&#13;&#10;  File "T:\InGame\Gameplay\Scripts\Server\areaserver.py", line 206, in c_api_server_tick&#13;&#10;  File "T:\InGame\Gameplay\Scripts\Server\zone.py", line 469, in update&#13;&#10;  File "T:\InGame\Gameplay\Scripts\Server\time_service.py", line 112, in update&#13;&#10;  File "T:\InGame\Gameplay\Scripts\Server\scheduling.py", line 217, in simulate&#13;&#10;  File "T:\InGame\Gameplay\Scripts\Server\elements.py", line 385, in _resume&#13;&#10;  File "T:\InGame\Gameplay\Scripts\Server\sims\sim.py", line 3755, in _process_interaction_gen&#13;&#10;  File "T:\InGame\Gameplay\Scripts\Server\interactions\interaction_queue.py", line 786, in process_one_interaction_gen&#13;&#10;  File "T:\InGame\Gameplay\Scripts\Server\interactions\si_state.py", line 944, in process_gen&#13;&#10;  File "T:\InGame\Gameplay\Scripts\Server\interactions\si_state.py", line 323, in remove_gen&#13;&#10;  File "T:\InGame\Gameplay\Scripts\Server\interactions\si_state.py", line 1143, in _remove_gen&#13;&#10;  File "T:\InGame\Gameplay\Scripts\Server\interactions\base\super_interaction.py", line 4945, in on_removed_from_si_state&#13;&#10;  File "T:\InGame\Gameplay\Scripts\Server\interactions\base\super_interaction.py", line 4957, in _exited_pipeline&#13;&#10;  File "T:\InGame\Gameplay\Scripts\Server\interactions\base\interaction.py", line 6718, in _exited_pipeline&#13;&#10;  File "T:\InGame\Gameplay\Scripts\Server\interactions\base\interaction.py", line 5781, in _trigger_interaction_complete_test_event&#13;&#10;  File "T:\InGame\Gameplay\Scripts\Server\event_testing\event_manager_service.py", line 262, in process_event&#13;&#10;  File "T:\InGame\Gameplay\Scripts\Server\event_testing\event_manager_service.py", line 371, in _process_test_event&#13;&#10;  File "T:\InGame\Gameplay\Scripts\Server\event_testing\test_events.py", line 174, in wrapper&#13;&#10;KeyError: (&lt;event_testing.tests_with_data.TotalTimeElapsedByTagTest object at 0x00007FF48B742390&gt;, frozenset({('objective_guid64', 25807), ('data_object', &lt;event_testing.event_data_object.EventDataObject object at 0x00007FF48E01BAD0&gt;)}))&#13;&#10;&#13;&#10;During handling of the above exception, another exception occurred:&#13;&#10;&#13;&#10;Traceback (most recent call last):&#13;&#10;  File "T:\InGame\Gameplay\Scripts\Server\event_testing\event_manager_service.py", line 369, in _process_test_event&#13;&#10;  File "T:\InGame\Gameplay\Scripts\Server\aspirations\aspiration_tuning.py", line 64, in handle_event&#13;&#10;  File "T:\InGame\Gameplay\Scripts\Server\event_testing\event_data_tracker.py", line 185, in handle_event&#13;&#10;  File "T:\InGame\Gameplay\Scripts\Server\event_testing\objective_tuning.py", line 1046, in run_test&#13;&#10;  File "T:\InGame\Gameplay\Scripts\Server\event_testing\resolver.py", line 830, in __call__&#13;&#10;  File "T:\InGame\Gameplay\Scripts\Server\event_testing\resolver.py", line 130, in __call__&#13;&#10;  File "T:\InGame\Gameplay\Scripts\Server\event_testing\test_events.py", line 176, in wrapper&#13;&#10;  File "T:\InGame\Gameplay\Scripts\Server\event_testing\tests_with_data.py", line 1175, in __call__&#13;&#10;  File "T:\InGame\Gameplay\Scripts\Core\google\protobuf\internal\cpp_message.py", line 167, in __getitem__&#13;&#10;IndexError: list assignment index (0) out of range&#13;&#10;rtim=0&#13;&#10;Client Session Time: 31.45&#13; &#10;Num Save Errors: 0&#13; &#10;Num Load Errors: 0&#13; &#10;Current Game State: 0xdd4141d5&#13; &#10;Origin Version: 10,5,8,17910&#13; &#10;Modded: False&#13; &#10;SystemInfo: Windows 10 10.0.18363 GPU: Intel(R) HD Graphics igdumd64.dll 8.15.10.2900, GUID: D7B78E66-4306-11CF-9D79-0820B2C2C535&#13; &#10;</desyncdata></report>
<report><version>2</version><sessionid>b486a23b7565899d5e7a6056</sessionid><type>desync</type><sku>ea.maxis.sims4_64.15.pc</sku><createtime>2020-03-24 22:01:44</createtime><buildsignature>Local.Unknown.Unknown.1.61.15.1020-1.200.000.440.Release</buildsignature><categoryid>cpp_message.py:167</categoryid><desyncid>b486a23b7565899d5e7a6056</desyncid><systemconfig/><screenshot/><desyncdata>Exception raised while trying to run a test event in test_events.py: (IndexError: list assignment index (0) out of range)&#13;&#10;Traceback (most recent call last):&#13;&#10;Caught and logged:&#13;&#10;  File "T:\InGame\Gameplay\Scripts\Core\sims4\utils.py", line 179, in wrapper&#13;&#10;  File "T:\InGame\Gameplay\Scripts\Server\areaserver.py", line 206, in c_api_server_tick&#13;&#10;  File "T:\InGame\Gameplay\Scripts\Server\zone.py", line 469, in update&#13;&#10;  File "T:\InGame\Gameplay\Scripts\Server\time_service.py", line 112, in update&#13;&#10;  File "T:\InGame\Gameplay\Scripts\Server\scheduling.py", line 217, in simulate&#13;&#10;  File "T:\InGame\Gameplay\Scripts\Server\elements.py", line 385, in _resume&#13;&#10;  File "T:\InGame\Gameplay\Scripts\Server\sims\sim.py", line 3755, in _process_interaction_gen&#13;&#10;  File "T:\InGame\Gameplay\Scripts\Server\interactions\interaction_queue.py", line 786, in process_one_interaction_gen&#13;&#10;  File "T:\InGame\Gameplay\Scripts\Server\interactions\si_state.py", line 944, in process_gen&#13;&#10;  File "T:\InGame\Gameplay\Scripts\Server\interactions\si_state.py", line 323, in remove_gen&#13;&#10;  File "T:\InGame\Gameplay\Scripts\Server\interactions\si_state.py", line 1143, in _remove_gen&#13;&#10;  File "T:\InGame\Gameplay\Scripts\Server\interactions\base\super_interaction.py", line 4945, in on_removed_from_si_state&#13;&#10;  File "T:\InGame\Gameplay\Scripts\Server\interactions\base\super_interaction.py", line 4957, in _exited_pipeline&#13;&#10;  File "T:\InGame\Gameplay\Scripts\Server\interactions\base\interaction.py", line 6718, in _exited_pipeline&#13;&#10;  File "T:\InGame\Gameplay\Scripts\Server\interactions\base\interaction.py", line 5781, in _trigger_interaction_complete_test_event&#13;&#10;  File "T:\InGame\Gameplay\Scripts\Server\event_testing\event_manager_service.py", line 262, in process_event&#13;&#10;  File "T:\InGame\Gameplay\Scripts\Server\event_testing\event_manager_service.py", line 371, in _process_test_event&#13;&#10;  File "T:\InGame\Gameplay\Scripts\Server\event_testing\test_events.py", line 174, in wrapper&#13;&#10;KeyError: (&lt;event_testing.tests_with_data.TotalTimeElapsedByTagTest object at 0x00007FF48B742390&gt;, frozenset({('objective_guid64', 25807), ('data_object', &lt;event_testing.event_data_object.EventDataObject object at 0x00007FF48E01BAD0&gt;)}))&#13;&#10;&#13;&#10;During handling of the above exception, another exception occurred:&#13;&#10;&#13;&#10;Traceback (most recent call last):&#13;&#10;  File "T:\InGame\Gameplay\Scripts\Server\event_testing\event_manager_service.py", line 369, in _process_test_event&#13;&#10;  File "T:\InGame\Gameplay\Scripts\Server\aspirations\aspiration_tuning.py", line 64, in handle_event&#13;&#10;  File "T:\InGame\Gameplay\Scripts\Server\event_testing\event_data_tracker.py", line 185, in handle_event&#13;&#10;  File "T:\InGame\Gameplay\Scripts\Server\event_testing\objective_tuning.py", line 1046, in run_test&#13;&#10;  File "T:\InGame\Gameplay\Scripts\Server\event_testing\resolver.py", line 830, in __call__&#13;&#10;  File "T:\InGame\Gameplay\Scripts\Server\event_testing\resolver.py", line 130, in __call__&#13;&#10;  File "T:\InGame\Gameplay\Scripts\Server\event_testing\test_events.py", line 176, in wrapper&#13;&#10;  File "T:\InGame\Gameplay\Scripts\Server\event_testing\tests_with_data.py", line 1175, in __call__&#13;&#10;  File "T:\InGame\Gameplay\Scripts\Core\google\protobuf\internal\cpp_message.py", line 167, in __getitem__&#13;&#10;IndexError: list assignment index (0) out of range&#13;&#10;rtim=0&#13;&#10;Client Session Time: 31.45&#13; &#10;Num Save Errors: 0&#13; &#10;Num Load Errors: 0&#13; &#10;Current Game State: 0xdd4141d5&#13; &#10;Origin Version: 10,5,8,17910&#13; &#10;Modded: False&#13; &#10;SystemInfo: Windows 10 10.0.18363 GPU: Intel(R) HD Graphics igdumd64.dll 8.15.10.2900, GUID: D7B78E66-4306-11CF-9D79-0820B2C2C535&#13; &#10;</desyncdata></report>
<report><version>2</version><sessionid>b486a23b7565899d5e7a6056</sessionid><type>desync</type><sku>ea.maxis.sims4_64.15.pc</sku><createtime>2020-03-24 22:02:45</createtime><buildsignature>Local.Unknown.Unknown.1.61.15.1020-1.200.000.440.Release</buildsignature><categoryid>cpp_message.py:167</categoryid><desyncid>b486a23b7565899d5e7a6056</desyncid><systemconfig/><screenshot/><desyncdata>Exception raised while trying to run a test event in test_events.py: (IndexError: list assignment index (0) out of range)&#13;&#10;Traceback (most recent call last):&#13;&#10;Caught and logged:&#13;&#10;  File "T:\InGame\Gameplay\Scripts\Core\sims4\utils.py", line 179, in wrapper&#13;&#10;  File "T:\InGame\Gameplay\Scripts\Server\areaserver.py", line 206, in c_api_server_tick&#13;&#10;  File "T:\InGame\Gameplay\Scripts\Server\zone.py", line 469, in update&#13;&#10;  File "T:\InGame\Gameplay\Scripts\Server\time_service.py", line 112, in update&#13;&#10;  File "T:\InGame\Gameplay\Scripts\Server\scheduling.py", line 217, in simulate&#13;&#10;  File "T:\InGame\Gameplay\Scripts\Server\elements.py", line 385, in _resume&#13;&#10;  File "T:\InGame\Gameplay\Scripts\Server\sims\sim.py", line 3755, in _process_interaction_gen&#13;&#10;  File "T:\InGame\Gameplay\Scripts\Server\interactions\interaction_queue.py", line 786, in process_one_interaction_gen&#13;&#10;  File "T:\InGame\Gameplay\Scripts\Server\interactions\si_state.py", line 944, in process_gen&#13;&#10;  File "T:\InGame\Gameplay\Scripts\Server\interactions\si_state.py", line 323, in remove_gen&#13;&#10;  File "T:\InGame\Gameplay\Scripts\Server\interactions\si_state.py", line 1143, in _remove_gen&#13;&#10;  File "T:\InGame\Gameplay\Scripts\Server\interactions\base\super_interaction.py", line 4945, in on_removed_from_si_state&#13;&#10;  File "T:\InGame\Gameplay\Scripts\Server\interactions\base\super_interaction.py", line 4957, in _exited_pipeline&#13;&#10;  File "T:\InGame\Gameplay\Scripts\Server\interactions\base\interaction.py", line 6718, in _exited_pipeline&#13;&#10;  File "T:\InGame\Gameplay\Scripts\Server\interactions\base\interaction.py", line 5781, in _trigger_interaction_complete_test_event&#13;&#10;  File "T:\InGame\Gameplay\Scripts\Server\event_testing\event_manager_service.py", line 262, in process_event&#13;&#10;  File "T:\InGame\Gameplay\Scripts\Server\event_testing\event_manager_service.py", line 371, in _process_test_event&#13;&#10;  File "T:\InGame\Gameplay\Scripts\Server\event_testing\test_events.py", line 174, in wrapper&#13;&#10;KeyError: (&lt;event_testing.tests_with_data.TotalTimeElapsedByTagTest object at 0x00007FF48B742390&gt;, frozenset({('objective_guid64', 25807), ('data_object', &lt;event_testing.event_data_object.EventDataObject object at 0x00007FF48E01BAD0&gt;)}))&#13;&#10;&#13;&#10;During handling of the above exception, another exception occurred:&#13;&#10;&#13;&#10;Traceback (most recent call last):&#13;&#10;  File "T:\InGame\Gameplay\Scripts\Server\event_testing\event_manager_service.py", line 369, in _process_test_event&#13;&#10;  File "T:\InGame\Gameplay\Scripts\Server\aspirations\aspiration_tuning.py", line 64, in handle_event&#13;&#10;  File "T:\InGame\Gameplay\Scripts\Server\event_testing\event_data_tracker.py", line 185, in handle_event&#13;&#10;  File "T:\InGame\Gameplay\Scripts\Server\event_testing\objective_tuning.py", line 1046, in run_test&#13;&#10;  File "T:\InGame\Gameplay\Scripts\Server\event_testing\resolver.py", line 830, in __call__&#13;&#10;  File "T:\InGame\Gameplay\Scripts\Server\event_testing\resolver.py", line 130, in __call__&#13;&#10;  File "T:\InGame\Gameplay\Scripts\Server\event_testing\test_events.py", line 176, in wrapper&#13;&#10;  File "T:\InGame\Gameplay\Scripts\Server\event_testing\tests_with_data.py", line 1175, in __call__&#13;&#10;  File "T:\InGame\Gameplay\Scripts\Core\google\protobuf\internal\cpp_message.py", line 167, in __getitem__&#13;&#10;IndexError: list assignment index (0) out of range&#13;&#10;rtim=0&#13;&#10;Client Session Time: 31.45&#13; &#10;Num Save Errors: 0&#13; &#10;Num Load Errors: 0&#13; &#10;Current Game State: 0xdd4141d5&#13; &#10;Origin Version: 10,5,8,17910&#13; &#10;Modded: False&#13; &#10;SystemInfo: Windows 10 10.0.18363 GPU: Intel(R) HD Graphics igdumd64.dll 8.15.10.2900, GUID: D7B78E66-4306-11CF-9D79-0820B2C2C535&#13; &#10;</desyncdata></report>
<report><version>2</version><sessionid>b486a23b7565899d5e7a6056</sessionid><type>desync</type><sku>ea.maxis.sims4_64.15.pc</sku><createtime>2020-03-24 22:03:11</createtime><buildsignature>Local.Unknown.Unknown.1.61.15.1020-1.200.000.440.Release</buildsignature><categoryid>cpp_message.py:167</categoryid><desyncid>b486a23b7565899d5e7a6056</desyncid><systemconfig/><screenshot/><desyncdata>Exception raised while trying to run a test event in test_events.py: (IndexError: list assignment index (0) out of range)&#13;&#10;Traceback (most recent call last):&#13;&#10;Caught and logged:&#13;&#10;  File "T:\InGame\Gameplay\Scripts\Core\sims4\utils.py", line 179, in wrapper&#13;&#10;  File "T:\InGame\Gameplay\Scripts\Server\areaserver.py", line 206, in c_api_server_tick&#13;&#10;  File "T:\InGame\Gameplay\Scripts\Server\zone.py", line 469, in update&#13;&#10;  File "T:\InGame\Gameplay\Scripts\Server\time_service.py", line 112, in update&#13;&#10;  File "T:\InGame\Gameplay\Scripts\Server\scheduling.py", line 217, in simulate&#13;&#10;  File "T:\InGame\Gameplay\Scripts\Server\elements.py", line 385, in _resume&#13;&#10;  File "T:\InGame\Gameplay\Scripts\Server\sims\sim.py", line 3755, in _process_interaction_gen&#13;&#10;  File "T:\InGame\Gameplay\Scripts\Server\interactions\interaction_queue.py", line 786, in process_one_interaction_gen&#13;&#10;  File "T:\InGame\Gameplay\Scripts\Server\interactions\si_state.py", line 944, in process_gen&#13;&#10;  File "T:\InGame\Gameplay\Scripts\Server\interactions\si_state.py", line 323, in remove_gen&#13;&#10;  File "T:\InGame\Gameplay\Scripts\Server\interactions\si_state.py", line 1143, in _remove_gen&#13;&#10;  File "T:\InGame\Gameplay\Scripts\Server\interactions\base\super_interaction.py", line 4945, in on_removed_from_si_state&#13;&#10;  File "T:\InGame\Gameplay\Scripts\Server\interactions\base\super_interaction.py", line 4957, in _exited_pipeline&#13;&#10;  File "T:\InGame\Gameplay\Scripts\Server\interactions\base\interaction.py", line 6718, in _exited_pipeline&#13;&#10;  File "T:\InGame\Gameplay\Scripts\Server\interactions\base\interaction.py", line 5781, in _trigger_interaction_complete_test_event&#13;&#10;  File "T:\InGame\Gameplay\Scripts\Server\event_testing\event_manager_service.py", line 262, in process_event&#13;&#10;  File "T:\InGame\Gameplay\Scripts\Server\event_testing\event_manager_service.py", line 371, in _process_test_event&#13;&#10;  File "T:\InGame\Gameplay\Scripts\Server\event_testing\test_events.py", line 174, in wrapper&#13;&#10;KeyError: (&lt;event_testing.tests_with_data.TotalTimeElapsedByTagTest object at 0x00007FF48B742390&gt;, frozenset({('objective_guid64', 25807), ('data_object', &lt;event_testing.event_data_object.EventDataObject object at 0x00007FF48E01BAD0&gt;)}))&#13;&#10;&#13;&#10;During handling of the above exception, another exception occurred:&#13;&#10;&#13;&#10;Traceback (most recent call last):&#13;&#10;  File "T:\InGame\Gameplay\Scripts\Server\event_testing\event_manager_service.py", line 369, in _process_test_event&#13;&#10;  File "T:\InGame\Gameplay\Scripts\Server\aspirations\aspiration_tuning.py", line 64, in handle_event&#13;&#10;  File "T:\InGame\Gameplay\Scripts\Server\event_testing\event_data_tracker.py", line 185, in handle_event&#13;&#10;  File "T:\InGame\Gameplay\Scripts\Server\event_testing\objective_tuning.py", line 1046, in run_test&#13;&#10;  File "T:\InGame\Gameplay\Scripts\Server\event_testing\resolver.py", line 830, in __call__&#13;&#10;  File "T:\InGame\Gameplay\Scripts\Server\event_testing\resolver.py", line 130, in __call__&#13;&#10;  File "T:\InGame\Gameplay\Scripts\Server\event_testing\test_events.py", line 176, in wrapper&#13;&#10;  File "T:\InGame\Gameplay\Scripts\Server\event_testing\tests_with_data.py", line 1175, in __call__&#13;&#10;  File "T:\InGame\Gameplay\Scripts\Core\google\protobuf\internal\cpp_message.py", line 167, in __getitem__&#13;&#10;IndexError: list assignment index (0) out of range&#13;&#10;rtim=0&#13;&#10;Client Session Time: 31.45&#13; &#10;Num Save Errors: 0&#13; &#10;Num Load Errors: 0&#13; &#10;Current Game State: 0xdd4141d5&#13; &#10;Origin Version: 10,5,8,17910&#13; &#10;Modded: False&#13; &#10;SystemInfo: Windows 10 10.0.18363 GPU: Intel(R) HD Graphics igdumd64.dll 8.15.10.2900, GUID: D7B78E66-4306-11CF-9D79-0820B2C2C535&#13; &#10;</desyncdata></report>
<report><version>2</version><sessionid>b486a23b7565899d5e7a6056</sessionid><type>desync</type><sku>ea.maxis.sims4_64.15.pc</sku><createtime>2020-03-24 22:04:52</createtime><buildsignature>Local.Unknown.Unknown.1.61.15.1020-1.200.000.440.Release</buildsignature><categoryid>cpp_message.py:167</categoryid><desyncid>b486a23b7565899d5e7a6056</desyncid><systemconfig/><screenshot/><desyncdata>Exception raised while trying to run a test event in test_events.py: (IndexError: list assignment index (0) out of range)&#13;&#10;Traceback (most recent call last):&#13;&#10;Caught and logged:&#13;&#10;  File "T:\InGame\Gameplay\Scripts\Core\sims4\utils.py", line 179, in wrapper&#13;&#10;  File "T:\InGame\Gameplay\Scripts\Server\areaserver.py", line 206, in c_api_server_tick&#13;&#10;  File "T:\InGame\Gameplay\Scripts\Server\zone.py", line 469, in update&#13;&#10;  File "T:\InGame\Gameplay\Scripts\Server\time_service.py", line 112, in update&#13;&#10;  File "T:\InGame\Gameplay\Scripts\Server\scheduling.py", line 217, in simulate&#13;&#10;  File "T:\InGame\Gameplay\Scripts\Server\elements.py", line 385, in _resume&#13;&#10;  File "T:\InGame\Gameplay\Scripts\Server\sims\sim.py", line 3755, in _process_interaction_gen&#13;&#10;  File "T:\InGame\Gameplay\Scripts\Server\interactions\interaction_queue.py", line 786, in process_one_interaction_gen&#13;&#10;  File "T:\InGame\Gameplay\Scripts\Server\interactions\si_state.py", line 944, in process_gen&#13;&#10;  File "T:\InGame\Gameplay\Scripts\Server\interactions\si_state.py", line 323, in remove_gen&#13;&#10;  File "T:\InGame\Gameplay\Scripts\Server\interactions\si_state.py", line 1143, in _remove_gen&#13;&#10;  File "T:\InGame\Gameplay\Scripts\Server\interactions\base\super_interaction.py", line 4945, in on_removed_from_si_state&#13;&#10;  File "T:\InGame\Gameplay\Scripts\Server\interactions\base\super_interaction.py", line 4957, in _exited_pipeline&#13;&#10;  File "T:\InGame\Gameplay\Scripts\Server\interactions\base\interaction.py", line 6718, in _exited_pipeline&#13;&#10;  File "T:\InGame\Gameplay\Scripts\Server\interactions\base\interaction.py", line 5781, in _trigger_interaction_complete_test_event&#13;&#10;  File "T:\InGame\Gameplay\Scripts\Server\event_testing\event_manager_service.py", line 262, in process_event&#13;&#10;  File "T:\InGame\Gameplay\Scripts\Server\event_testing\event_manager_service.py", line 371, in _process_test_event&#13;&#10;  File "T:\InGame\Gameplay\Scripts\Server\event_testing\test_events.py", line 174, in wrapper&#13;&#10;KeyError: (&lt;event_testing.tests_with_data.TotalTimeElapsedByTagTest object at 0x00007FF48B742390&gt;, frozenset({('objective_guid64', 25807), ('data_object', &lt;event_testing.event_data_object.EventDataObject object at 0x00007FF48E01BAD0&gt;)}))&#13;&#10;&#13;&#10;During handling of the above exception, another exception occurred:&#13;&#10;&#13;&#10;Traceback (most recent call last):&#13;&#10;  File "T:\InGame\Gameplay\Scripts\Server\event_testing\event_manager_service.py", line 369, in _process_test_event&#13;&#10;  File "T:\InGame\Gameplay\Scripts\Server\aspirations\aspiration_tuning.py", line 64, in handle_event&#13;&#10;  File "T:\InGame\Gameplay\Scripts\Server\event_testing\event_data_tracker.py", line 185, in handle_event&#13;&#10;  File "T:\InGame\Gameplay\Scripts\Server\event_testing\objective_tuning.py", line 1046, in run_test&#13;&#10;  File "T:\InGame\Gameplay\Scripts\Server\event_testing\resolver.py", line 830, in __call__&#13;&#10;  File "T:\InGame\Gameplay\Scripts\Server\event_testing\resolver.py", line 130, in __call__&#13;&#10;  File "T:\InGame\Gameplay\Scripts\Server\event_testing\test_events.py", line 176, in wrapper&#13;&#10;  File "T:\InGame\Gameplay\Scripts\Server\event_testing\tests_with_data.py", line 1175, in __call__&#13;&#10;  File "T:\InGame\Gameplay\Scripts\Core\google\protobuf\internal\cpp_message.py", line 167, in __getitem__&#13;&#10;IndexError: list assignment index (0) out of range&#13;&#10;rtim=0&#13;&#10;Client Session Time: 31.45&#13; &#10;Num Save Errors: 0&#13; &#10;Num Load Errors: 0&#13; &#10;Current Game State: 0xdd4141d5&#13; &#10;Origin Version: 10,5,8,17910&#13; &#10;Modded: False&#13; &#10;SystemInfo: Windows 10 10.0.18363 GPU: Intel(R) HD Graphics igdumd64.dll 8.15.10.2900, GUID: D7B78E66-4306-11CF-9D79-0820B2C2C535&#13; &#10;</desyncdata></report>
<report><version>2</version><sessionid>b486a23b7565899d5e7a6056</sessionid><type>desync</type><sku>ea.maxis.sims4_64.15.pc</sku><createtime>2020-03-24 22:06:22</createtime><buildsignature>Local.Unknown.Unknown.1.61.15.1020-1.200.000.440.Release</buildsignature><categoryid>cpp_message.py:167</categoryid><desyncid>b486a23b7565899d5e7a6056</desyncid><systemconfig/><screenshot/><desyncdata>Exception raised while trying to run a test event in test_events.py: (IndexError: list assignment index (0) out of range)&#13;&#10;Traceback (most recent call last):&#13;&#10;Caught and logged:&#13;&#10;  File "T:\InGame\Gameplay\Scripts\Core\sims4\utils.py", line 179, in wrapper&#13;&#10;  File "T:\InGame\Gameplay\Scripts\Server\areaserver.py", line 206, in c_api_server_tick&#13;&#10;  File "T:\InGame\Gameplay\Scripts\Server\zone.py", line 469, in update&#13;&#10;  File "T:\InGame\Gameplay\Scripts\Server\time_service.py", line 112, in update&#13;&#10;  File "T:\InGame\Gameplay\Scripts\Server\scheduling.py", line 217, in simulate&#13;&#10;  File "T:\InGame\Gameplay\Scripts\Server\elements.py", line 385, in _resume&#13;&#10;  File "T:\InGame\Gameplay\Scripts\Server\sims\sim.py", line 3755, in _process_interaction_gen&#13;&#10;  File "T:\InGame\Gameplay\Scripts\Server\interactions\interaction_queue.py", line 786, in process_one_interaction_gen&#13;&#10;  File "T:\InGame\Gameplay\Scripts\Server\interactions\si_state.py", line 944, in process_gen&#13;&#10;  File "T:\InGame\Gameplay\Scripts\Server\interactions\si_state.py", line 323, in remove_gen&#13;&#10;  File "T:\InGame\Gameplay\Scripts\Server\interactions\si_state.py", line 1143, in _remove_gen&#13;&#10;  File "T:\InGame\Gameplay\Scripts\Server\interactions\base\super_interaction.py", line 4945, in on_removed_from_si_state&#13;&#10;  File "T:\InGame\Gameplay\Scripts\Server\interactions\base\super_interaction.py", line 4957, in _exited_pipeline&#13;&#10;  File "T:\InGame\Gameplay\Scripts\Server\interactions\base\interaction.py", line 6718, in _exited_pipeline&#13;&#10;  File "T:\InGame\Gameplay\Scripts\Server\interactions\base\interaction.py", line 5781, in _trigger_interaction_complete_test_event&#13;&#10;  File "T:\InGame\Gameplay\Scripts\Server\event_testing\event_manager_service.py", line 262, in process_event&#13;&#10;  File "T:\InGame\Gameplay\Scripts\Server\event_testing\event_manager_service.py", line 371, in _process_test_event&#13;&#10;  File "T:\InGame\Gameplay\Scripts\Server\event_testing\test_events.py", line 174, in wrapper&#13;&#10;KeyError: (&lt;event_testing.tests_with_data.TotalTimeElapsedByTagTest object at 0x00007FF48B742390&gt;, frozenset({('objective_guid64', 25807), ('data_object', &lt;event_testing.event_data_object.EventDataObject object at 0x00007FF48E01BAD0&gt;)}))&#13;&#10;&#13;&#10;During handling of the above exception, another exception occurred:&#13;&#10;&#13;&#10;Traceback (most recent call last):&#13;&#10;  File "T:\InGame\Gameplay\Scripts\Server\event_testing\event_manager_service.py", line 369, in _process_test_event&#13;&#10;  File "T:\InGame\Gameplay\Scripts\Server\aspirations\aspiration_tuning.py", line 64, in handle_event&#13;&#10;  File "T:\InGame\Gameplay\Scripts\Server\event_testing\event_data_tracker.py", line 185, in handle_event&#13;&#10;  File "T:\InGame\Gameplay\Scripts\Server\event_testing\objective_tuning.py", line 1046, in run_test&#13;&#10;  File "T:\InGame\Gameplay\Scripts\Server\event_testing\resolver.py", line 830, in __call__&#13;&#10;  File "T:\InGame\Gameplay\Scripts\Server\event_testing\resolver.py", line 130, in __call__&#13;&#10;  File "T:\InGame\Gameplay\Scripts\Server\event_testing\test_events.py", line 176, in wrapper&#13;&#10;  File "T:\InGame\Gameplay\Scripts\Server\event_testing\tests_with_data.py", line 1175, in __call__&#13;&#10;  File "T:\InGame\Gameplay\Scripts\Core\google\protobuf\internal\cpp_message.py", line 167, in __getitem__&#13;&#10;IndexError: list assignment index (0) out of range&#13;&#10;rtim=0&#13;&#10;Client Session Time: 31.45&#13; &#10;Num Save Errors: 0&#13; &#10;Num Load Errors: 0&#13; &#10;Current Game State: 0xdd4141d5&#13; &#10;Origin Version: 10,5,8,17910&#13; &#10;Modded: False&#13; &#10;SystemInfo: Windows 10 10.0.18363 GPU: Intel(R) HD Graphics igdumd64.dll 8.15.10.2900, GUID: D7B78E66-4306-11CF-9D79-0820B2C2C535&#13; &#10;</desyncdata></report>
</root>